ERROR 2025-09-30 14:02:15,251 log Internal Server Error: /api/auth/refresh/
Traceback (most recent call last):
  File "C:\Github\WildLitz-Capstone\venv\Lib\site-packages\django\core\handlers\exception.py", line 55, in inner
    response = get_response(request)
  File "C:\Github\WildLitz-Capstone\venv\Lib\site-packages\django\core\handlers\base.py", line 197, in _get_response
    response = wrapped_callback(request, *callback_args, **callback_kwargs)
  File "C:\Github\WildLitz-Capstone\venv\Lib\site-packages\django\views\decorators\csrf.py", line 65, in _view_wrapper
    return view_func(request, *args, **kwargs)
  File "C:\Github\WildLitz-Capstone\venv\Lib\site-packages\django\views\generic\base.py", line 105, in view
    return self.dispatch(request, *args, **kwargs)
           ~~~~~~~~~~~~~^^^^^^^^^^^^^^^^^^^^^^^^^^
  File "C:\Github\WildLitz-Capstone\venv\Lib\site-packages\rest_framework\views.py", line 515, in dispatch
    response = self.handle_exception(exc)
  File "C:\Github\WildLitz-Capstone\venv\Lib\site-packages\rest_framework\views.py", line 475, in handle_exception
    self.raise_uncaught_exception(exc)
    ~~~~~~~~~~~~~~~~~~~~~~~~~~~~~^^^^^
  File "C:\Github\WildLitz-Capstone\venv\Lib\site-packages\rest_framework\views.py", line 486, in raise_uncaught_exception
    raise exc
  File "C:\Github\WildLitz-Capstone\venv\Lib\site-packages\rest_framework\views.py", line 512, in dispatch
    response = handler(request, *args, **kwargs)
  File "C:\Github\WildLitz-Capstone\venv\Lib\site-packages\rest_framework_simplejwt\views.py", line 46, in post
    serializer.is_valid(raise_exception=True)
    ~~~~~~~~~~~~~~~~~~~^^^^^^^^^^^^^^^^^^^^^^
  File "C:\Github\WildLitz-Capstone\venv\Lib\site-packages\rest_framework\serializers.py", line 225, in is_valid
    self._validated_data = self.run_validation(self.initial_data)
                           ~~~~~~~~~~~~~~~~~~~^^^^^^^^^^^^^^^^^^^
  File "C:\Github\WildLitz-Capstone\venv\Lib\site-packages\rest_framework\serializers.py", line 447, in run_validation
    value = self.validate(value)
  File "C:\Github\WildLitz-Capstone\venv\Lib\site-packages\rest_framework_simplejwt\serializers.py", line 116, in validate
    user := get_user_model().objects.get(
            ~~~~~~~~~~~~~~~~~~~~~~~~~~~~^
        **{api_settings.USER_ID_FIELD: user_id}
        ^^^^^^^^^^^^^^^^^^^^^^^^^^^^^^^^^^^^^^^
    )
    ^
  File "C:\Github\WildLitz-Capstone\venv\Lib\site-packages\django\db\models\manager.py", line 87, in manager_method
    return getattr(self.get_queryset(), name)(*args, **kwargs)
           ~~~~~~~~~~~~~~~~~~~~~~~~~~~~~~~~~~^^^^^^^^^^^^^^^^^
  File "C:\Github\WildLitz-Capstone\venv\Lib\site-packages\django\db\models\query.py", line 633, in get
    raise self.model.DoesNotExist(
        "%s matching query does not exist." % self.model._meta.object_name
    )
django.contrib.auth.models.User.DoesNotExist: User matching query does not exist.
ERROR 2025-09-30 14:02:15,256 basehttp "POST /api/auth/refresh/ HTTP/1.1" 500 125708
ERROR 2025-09-30 14:02:15,256 basehttp "POST /api/auth/refresh/ HTTP/1.1" 500 125708
ERROR 2025-09-30 14:02:15,293 log Internal Server Error: /api/auth/refresh/
Traceback (most recent call last):
  File "C:\Github\WildLitz-Capstone\venv\Lib\site-packages\django\core\handlers\exception.py", line 55, in inner
    response = get_response(request)
  File "C:\Github\WildLitz-Capstone\venv\Lib\site-packages\django\core\handlers\base.py", line 197, in _get_response
    response = wrapped_callback(request, *callback_args, **callback_kwargs)
  File "C:\Github\WildLitz-Capstone\venv\Lib\site-packages\django\views\decorators\csrf.py", line 65, in _view_wrapper
    return view_func(request, *args, **kwargs)
  File "C:\Github\WildLitz-Capstone\venv\Lib\site-packages\django\views\generic\base.py", line 105, in view
    return self.dispatch(request, *args, **kwargs)
           ~~~~~~~~~~~~~^^^^^^^^^^^^^^^^^^^^^^^^^^
  File "C:\Github\WildLitz-Capstone\venv\Lib\site-packages\rest_framework\views.py", line 515, in dispatch
    response = self.handle_exception(exc)
  File "C:\Github\WildLitz-Capstone\venv\Lib\site-packages\rest_framework\views.py", line 475, in handle_exception
    self.raise_uncaught_exception(exc)
    ~~~~~~~~~~~~~~~~~~~~~~~~~~~~~^^^^^
  File "C:\Github\WildLitz-Capstone\venv\Lib\site-packages\rest_framework\views.py", line 486, in raise_uncaught_exception
    raise exc
  File "C:\Github\WildLitz-Capstone\venv\Lib\site-packages\rest_framework\views.py", line 512, in dispatch
    response = handler(request, *args, **kwargs)
  File "C:\Github\WildLitz-Capstone\venv\Lib\site-packages\rest_framework_simplejwt\views.py", line 46, in post
    serializer.is_valid(raise_exception=True)
    ~~~~~~~~~~~~~~~~~~~^^^^^^^^^^^^^^^^^^^^^^
  File "C:\Github\WildLitz-Capstone\venv\Lib\site-packages\rest_framework\serializers.py", line 225, in is_valid
    self._validated_data = self.run_validation(self.initial_data)
                           ~~~~~~~~~~~~~~~~~~~^^^^^^^^^^^^^^^^^^^
  File "C:\Github\WildLitz-Capstone\venv\Lib\site-packages\rest_framework\serializers.py", line 447, in run_validation
    value = self.validate(value)
  File "C:\Github\WildLitz-Capstone\venv\Lib\site-packages\rest_framework_simplejwt\serializers.py", line 116, in validate
    user := get_user_model().objects.get(
            ~~~~~~~~~~~~~~~~~~~~~~~~~~~~^
        **{api_settings.USER_ID_FIELD: user_id}
        ^^^^^^^^^^^^^^^^^^^^^^^^^^^^^^^^^^^^^^^
    )
    ^
  File "C:\Github\WildLitz-Capstone\venv\Lib\site-packages\django\db\models\manager.py", line 87, in manager_method
    return getattr(self.get_queryset(), name)(*args, **kwargs)
           ~~~~~~~~~~~~~~~~~~~~~~~~~~~~~~~~~~^^^^^^^^^^^^^^^^^
  File "C:\Github\WildLitz-Capstone\venv\Lib\site-packages\django\db\models\query.py", line 633, in get
    raise self.model.DoesNotExist(
        "%s matching query does not exist." % self.model._meta.object_name
    )
django.contrib.auth.models.User.DoesNotExist: User matching query does not exist.
ERROR 2025-09-30 14:02:15,295 basehttp "POST /api/auth/refresh/ HTTP/1.1" 500 125708
ERROR 2025-09-30 14:02:15,295 basehttp "POST /api/auth/refresh/ HTTP/1.1" 500 125708
ERROR 2025-09-30 16:40:50,275 views Error checking word existence: {'message': 'permission denied for schema wildlitz', 'code': '42501', 'hint': None, 'details': None}
ERROR 2025-09-30 16:40:50,277 log Internal Server Error: /api/syllabification/check-word-exists/
ERROR 2025-09-30 16:40:50,278 basehttp "GET /api/syllabification/check-word-exists/?word=butterfly HTTP/1.1" 500 112
ERROR 2025-09-30 16:40:50,278 basehttp "GET /api/syllabification/check-word-exists/?word=butterfly HTTP/1.1" 500 112
ERROR 2025-09-30 16:42:32,818 views Error checking word existence: {'message': 'column w.pronunciation_guide does not exist', 'code': '42703', 'hint': None, 'details': None}
ERROR 2025-09-30 16:42:32,820 log Internal Server Error: /api/syllabification/check-word-exists/
ERROR 2025-09-30 16:42:32,820 basehttp "GET /api/syllabification/check-word-exists/?word=butterfly HTTP/1.1" 500 118
ERROR 2025-09-30 16:42:32,820 basehttp "GET /api/syllabification/check-word-exists/?word=butterfly HTTP/1.1" 500 118
ERROR 2025-09-30 16:43:10,787 views Error checking word existence: {'message': 'column w.pronunciation_guide does not exist', 'code': '42703', 'hint': None, 'details': None}
ERROR 2025-09-30 16:43:10,788 log Internal Server Error: /api/syllabification/check-word-exists/
ERROR 2025-09-30 16:43:10,788 basehttp "GET /api/syllabification/check-word-exists/?word=butterfly HTTP/1.1" 500 118
ERROR 2025-09-30 16:43:10,788 basehttp "GET /api/syllabification/check-word-exists/?word=butterfly HTTP/1.1" 500 118
ERROR 2025-09-30 17:05:05,679 views Error fetching custom words: {'message': 'column syllable_words.is_custom does not exist', 'code': '42703', 'hint': None, 'details': None}
ERROR 2025-09-30 17:05:05,685 log Internal Server Error: /api/syllabification/get-custom-words/
ERROR 2025-09-30 17:05:05,686 basehttp "GET /api/syllabification/get-custom-words/ HTTP/1.1" 500 121
ERROR 2025-09-30 17:05:05,686 basehttp "GET /api/syllabification/get-custom-words/ HTTP/1.1" 500 121
ERROR 2025-09-30 20:28:57,309 views Error creating custom word: {'message': 'null value in column "id" of relation "syllable_words" violates not-null constraint', 'code': '23502', 'hint': None, 'details': 'Failing row contains (null, moonlight, moon-light, 2, easy, Nature, null, null, null, [], Moonlight is actually sunlight reflected off the moon! It\'s a ma..., Hey there! Let\'s clap out the word \'moonlight\' together! Ready? ..., Nature, t, {"confidence": 0.95, "is_correct": true, "suggestion": "The brea..., null, Anonymous, t, t, 0, 0.00, null).'}
ERROR 2025-09-30 20:28:57,327 views Traceback (most recent call last):
  File "C:\Github\WildLitz-Capstone\backend\wildlitz\syllabification\views.py", line 593, in create_custom_word
    }).execute()
       ~~~~~~~^^
  File "C:\Github\WildLitz-Capstone\venv\Lib\site-packages\postgrest\_sync\request_builder.py", line 126, in execute
    raise APIError(dict(json_obj))
postgrest.exceptions.APIError: {'message': 'null value in column "id" of relation "syllable_words" violates not-null constraint', 'code': '23502', 'hint': None, 'details': 'Failing row contains (null, moonlight, moon-light, 2, easy, Nature, null, null, null, [], Moonlight is actually sunlight reflected off the moon! It\'s a ma..., Hey there! Let\'s clap out the word \'moonlight\' together! Ready? ..., Nature, t, {"confidence": 0.95, "is_correct": true, "suggestion": "The brea..., null, Anonymous, t, t, 0, 0.00, null).'}

ERROR 2025-09-30 20:30:11,052 views Error creating custom word: {'message': 'null value in column "id" of relation "syllable_words" violates not-null constraint', 'code': '23502', 'hint': None, 'details': 'Failing row contains (null, moonlight, moon-light, 2, easy, Nature, null, null, null, [], Moonlight is not its own light; it\'s actually sunlight reflectin..., Let\'s explore the magical word "moonlight" together! Clap it out..., Nature, t, {"confidence": 0.95, "is_correct": true, "suggestion": "The brea..., null, Anonymous, t, t, 0, 0.00, null).'}
ERROR 2025-09-30 20:30:11,053 views Traceback (most recent call last):
  File "C:\Github\WildLitz-Capstone\backend\wildlitz\syllabification\views.py", line 593, in create_custom_word
    }).execute()
       ~~~~~~~^^
  File "C:\Github\WildLitz-Capstone\venv\Lib\site-packages\postgrest\_sync\request_builder.py", line 126, in execute
    raise APIError(dict(json_obj))
postgrest.exceptions.APIError: {'message': 'null value in column "id" of relation "syllable_words" violates not-null constraint', 'code': '23502', 'hint': None, 'details': 'Failing row contains (null, moonlight, moon-light, 2, easy, Nature, null, null, null, [], Moonlight is not its own light; it\'s actually sunlight reflectin..., Let\'s explore the magical word "moonlight" together! Clap it out..., Nature, t, {"confidence": 0.95, "is_correct": true, "suggestion": "The brea..., null, Anonymous, t, t, 0, 0.00, null).'}

ERROR 2025-09-30 21:17:21,578 views Error searching words: name 'is_custom' is not defined
ERROR 2025-09-30 21:17:21,582 log Internal Server Error: /api/syllabification/search-words/
ERROR 2025-09-30 21:17:21,582 basehttp "GET /api/syllabification/search-words/?q=&page=1&has_audio=false HTTP/1.1" 500 43
ERROR 2025-09-30 21:17:21,582 basehttp "GET /api/syllabification/search-words/?q=&page=1&has_audio=false HTTP/1.1" 500 43
ERROR 2025-09-30 21:17:21,585 views Error searching words: name 'is_custom' is not defined
ERROR 2025-09-30 21:17:21,586 log Internal Server Error: /api/syllabification/search-words/
ERROR 2025-09-30 21:17:21,587 basehttp "GET /api/syllabification/search-words/?q=&page=1&has_audio=false HTTP/1.1" 500 43
ERROR 2025-09-30 21:17:21,587 basehttp "GET /api/syllabification/search-words/?q=&page=1&has_audio=false HTTP/1.1" 500 43
ERROR 2025-09-30 21:18:28,621 views Error searching words: name 'is_custom' is not defined
ERROR 2025-09-30 21:18:28,622 log Internal Server Error: /api/syllabification/search-words/
ERROR 2025-09-30 21:18:28,623 basehttp "GET /api/syllabification/search-words/?q=&page=1&has_audio=false HTTP/1.1" 500 43
ERROR 2025-09-30 21:18:28,623 basehttp "GET /api/syllabification/search-words/?q=&page=1&has_audio=false HTTP/1.1" 500 43
ERROR 2025-09-30 21:18:28,625 views Error searching words: name 'is_custom' is not defined
ERROR 2025-09-30 21:18:28,626 log Internal Server Error: /api/syllabification/search-words/
ERROR 2025-09-30 21:18:28,627 basehttp "GET /api/syllabification/search-words/?q=&page=1&has_audio=false HTTP/1.1" 500 43
ERROR 2025-09-30 21:18:28,627 basehttp "GET /api/syllabification/search-words/?q=&page=1&has_audio=false HTTP/1.1" 500 43
ERROR 2025-09-30 21:18:37,732 views Error searching words: name 'is_custom' is not defined
ERROR 2025-09-30 21:18:37,732 log Internal Server Error: /api/syllabification/search-words/
ERROR 2025-09-30 21:18:37,733 basehttp "GET /api/syllabification/search-words/?q=&page=1&has_audio=false HTTP/1.1" 500 43
ERROR 2025-09-30 21:18:37,733 basehttp "GET /api/syllabification/search-words/?q=&page=1&has_audio=false HTTP/1.1" 500 43
ERROR 2025-09-30 21:18:37,736 views Error searching words: name 'is_custom' is not defined
ERROR 2025-09-30 21:18:37,737 log Internal Server Error: /api/syllabification/search-words/
ERROR 2025-09-30 21:18:37,738 basehttp "GET /api/syllabification/search-words/?q=&page=1&has_audio=false HTTP/1.1" 500 43
ERROR 2025-09-30 21:18:37,738 basehttp "GET /api/syllabification/search-words/?q=&page=1&has_audio=false HTTP/1.1" 500 43
ERROR 2025-09-30 21:18:41,481 views Error searching words: name 'is_custom' is not defined
ERROR 2025-09-30 21:18:41,484 log Internal Server Error: /api/syllabification/search-words/
ERROR 2025-09-30 21:18:41,485 basehttp "GET /api/syllabification/search-words/?q=ca&page=1&has_audio=false&categories%5B%5D=Animals HTTP/1.1" 500 43
ERROR 2025-09-30 21:18:41,485 basehttp "GET /api/syllabification/search-words/?q=ca&page=1&has_audio=false&categories%5B%5D=Animals HTTP/1.1" 500 43
ERROR 2025-09-30 21:18:42,965 views Error searching words: name 'is_custom' is not defined
ERROR 2025-09-30 21:18:42,968 log Internal Server Error: /api/syllabification/search-words/
ERROR 2025-09-30 21:18:42,968 basehttp "GET /api/syllabification/search-words/?q=ca&page=1&has_audio=false&categories%5B%5D=Animals&categories%5B%5D=Fruits HTTP/1.1" 500 43
ERROR 2025-09-30 21:18:42,968 basehttp "GET /api/syllabification/search-words/?q=ca&page=1&has_audio=false&categories%5B%5D=Animals&categories%5B%5D=Fruits HTTP/1.1" 500 43
ERROR 2025-09-30 21:20:58,231 views Error searching words: name 'is_custom' is not defined
ERROR 2025-09-30 21:20:58,232 log Internal Server Error: /api/syllabification/search-words/
ERROR 2025-09-30 21:20:58,232 basehttp "GET /api/syllabification/search-words/?q=&page=1&has_audio=false HTTP/1.1" 500 43
ERROR 2025-09-30 21:20:58,232 basehttp "GET /api/syllabification/search-words/?q=&page=1&has_audio=false HTTP/1.1" 500 43
ERROR 2025-09-30 21:20:58,234 views Error searching words: name 'is_custom' is not defined
ERROR 2025-09-30 21:20:58,235 log Internal Server Error: /api/syllabification/search-words/
ERROR 2025-09-30 21:20:58,236 basehttp "GET /api/syllabification/search-words/?q=&page=1&has_audio=false HTTP/1.1" 500 43
ERROR 2025-09-30 21:20:58,236 basehttp "GET /api/syllabification/search-words/?q=&page=1&has_audio=false HTTP/1.1" 500 43
ERROR 2025-09-30 21:20:59,732 views Error searching words: name 'is_custom' is not defined
ERROR 2025-09-30 21:20:59,732 log Internal Server Error: /api/syllabification/search-words/
ERROR 2025-09-30 21:20:59,734 basehttp "GET /api/syllabification/search-words/?q=&page=1&has_audio=false&categories%5B%5D=Food HTTP/1.1" 500 43
ERROR 2025-09-30 21:20:59,734 basehttp "GET /api/syllabification/search-words/?q=&page=1&has_audio=false&categories%5B%5D=Food HTTP/1.1" 500 43
ERROR 2025-09-30 21:21:52,661 views Error searching words: name 'is_custom' is not defined
ERROR 2025-09-30 21:21:52,663 log Internal Server Error: /api/syllabification/search-words/
ERROR 2025-09-30 21:21:52,663 basehttp "GET /api/syllabification/search-words/?q=&page=1&has_audio=false HTTP/1.1" 500 43
ERROR 2025-09-30 21:21:52,663 basehttp "GET /api/syllabification/search-words/?q=&page=1&has_audio=false HTTP/1.1" 500 43
ERROR 2025-09-30 21:21:52,665 views Error searching words: name 'is_custom' is not defined
ERROR 2025-09-30 21:21:52,666 log Internal Server Error: /api/syllabification/search-words/
ERROR 2025-09-30 21:21:52,666 basehttp "GET /api/syllabification/search-words/?q=&page=1&has_audio=false HTTP/1.1" 500 43
ERROR 2025-09-30 21:21:52,666 basehttp "GET /api/syllabification/search-words/?q=&page=1&has_audio=false HTTP/1.1" 500 43
