ERROR 2025-10-02 11:14:52,684 log Internal Server Error: /api/auth/refresh/
Traceback (most recent call last):
  File "C:\Users\Acer\AppData\Roaming\Python\Python313\site-packages\django\core\handlers\exception.py", line 55, in inner
    response = get_response(request)
  File "C:\Users\Acer\AppData\Roaming\Python\Python313\site-packages\django\core\handlers\base.py", line 197, in _get_response
    response = wrapped_callback(request, *callback_args, **callback_kwargs)
  File "C:\Users\Acer\AppData\Roaming\Python\Python313\site-packages\django\views\decorators\csrf.py", line 65, in _view_wrapper
    return view_func(request, *args, **kwargs)
  File "C:\Users\Acer\AppData\Roaming\Python\Python313\site-packages\django\views\generic\base.py", line 105, in view
    return self.dispatch(request, *args, **kwargs)
           ~~~~~~~~~~~~~^^^^^^^^^^^^^^^^^^^^^^^^^^
  File "C:\Users\Acer\AppData\Roaming\Python\Python313\site-packages\rest_framework\views.py", line 515, in dispatch
    response = self.handle_exception(exc)
  File "C:\Users\Acer\AppData\Roaming\Python\Python313\site-packages\rest_framework\views.py", line 475, in handle_exception
    self.raise_uncaught_exception(exc)
    ~~~~~~~~~~~~~~~~~~~~~~~~~~~~~^^^^^
  File "C:\Users\Acer\AppData\Roaming\Python\Python313\site-packages\rest_framework\views.py", line 486, in raise_uncaught_exception
    raise exc
  File "C:\Users\Acer\AppData\Roaming\Python\Python313\site-packages\rest_framework\views.py", line 512, in dispatch
    response = handler(request, *args, **kwargs)
  File "C:\Users\Acer\AppData\Roaming\Python\Python313\site-packages\rest_framework_simplejwt\views.py", line 46, in post
    serializer.is_valid(raise_exception=True)
    ~~~~~~~~~~~~~~~~~~~^^^^^^^^^^^^^^^^^^^^^^
  File "C:\Users\Acer\AppData\Roaming\Python\Python313\site-packages\rest_framework\serializers.py", line 225, in is_valid
    self._validated_data = self.run_validation(self.initial_data)
                           ~~~~~~~~~~~~~~~~~~~^^^^^^^^^^^^^^^^^^^
  File "C:\Users\Acer\AppData\Roaming\Python\Python313\site-packages\rest_framework\serializers.py", line 447, in run_validation
    value = self.validate(value)
  File "C:\Users\Acer\AppData\Roaming\Python\Python313\site-packages\rest_framework_simplejwt\serializers.py", line 116, in validate
    user := get_user_model().objects.get(
            ~~~~~~~~~~~~~~~~~~~~~~~~~~~~^
        **{api_settings.USER_ID_FIELD: user_id}
        ^^^^^^^^^^^^^^^^^^^^^^^^^^^^^^^^^^^^^^^
    )
    ^
  File "C:\Users\Acer\AppData\Roaming\Python\Python313\site-packages\django\db\models\manager.py", line 87, in manager_method
    return getattr(self.get_queryset(), name)(*args, **kwargs)
           ~~~~~~~~~~~~~~~~~~~~~~~~~~~~~~~~~~^^^^^^^^^^^^^^^^^
  File "C:\Users\Acer\AppData\Roaming\Python\Python313\site-packages\django\db\models\query.py", line 633, in get
    raise self.model.DoesNotExist(
        "%s matching query does not exist." % self.model._meta.object_name
    )
django.contrib.auth.models.User.DoesNotExist: User matching query does not exist.
ERROR 2025-10-02 11:14:52,685 log Internal Server Error: /api/auth/refresh/
Traceback (most recent call last):
  File "C:\Users\Acer\AppData\Roaming\Python\Python313\site-packages\django\core\handlers\exception.py", line 55, in inner
    response = get_response(request)
  File "C:\Users\Acer\AppData\Roaming\Python\Python313\site-packages\django\core\handlers\base.py", line 197, in _get_response
    response = wrapped_callback(request, *callback_args, **callback_kwargs)
  File "C:\Users\Acer\AppData\Roaming\Python\Python313\site-packages\django\views\decorators\csrf.py", line 65, in _view_wrapper
    return view_func(request, *args, **kwargs)
  File "C:\Users\Acer\AppData\Roaming\Python\Python313\site-packages\django\views\generic\base.py", line 105, in view
    return self.dispatch(request, *args, **kwargs)
           ~~~~~~~~~~~~~^^^^^^^^^^^^^^^^^^^^^^^^^^
  File "C:\Users\Acer\AppData\Roaming\Python\Python313\site-packages\rest_framework\views.py", line 515, in dispatch
    response = self.handle_exception(exc)
  File "C:\Users\Acer\AppData\Roaming\Python\Python313\site-packages\rest_framework\views.py", line 475, in handle_exception
    self.raise_uncaught_exception(exc)
    ~~~~~~~~~~~~~~~~~~~~~~~~~~~~~^^^^^
  File "C:\Users\Acer\AppData\Roaming\Python\Python313\site-packages\rest_framework\views.py", line 486, in raise_uncaught_exception
    raise exc
  File "C:\Users\Acer\AppData\Roaming\Python\Python313\site-packages\rest_framework\views.py", line 512, in dispatch
    response = handler(request, *args, **kwargs)
  File "C:\Users\Acer\AppData\Roaming\Python\Python313\site-packages\rest_framework_simplejwt\views.py", line 46, in post
    serializer.is_valid(raise_exception=True)
    ~~~~~~~~~~~~~~~~~~~^^^^^^^^^^^^^^^^^^^^^^
  File "C:\Users\Acer\AppData\Roaming\Python\Python313\site-packages\rest_framework\serializers.py", line 225, in is_valid
    self._validated_data = self.run_validation(self.initial_data)
                           ~~~~~~~~~~~~~~~~~~~^^^^^^^^^^^^^^^^^^^
  File "C:\Users\Acer\AppData\Roaming\Python\Python313\site-packages\rest_framework\serializers.py", line 447, in run_validation
    value = self.validate(value)
  File "C:\Users\Acer\AppData\Roaming\Python\Python313\site-packages\rest_framework_simplejwt\serializers.py", line 116, in validate
    user := get_user_model().objects.get(
            ~~~~~~~~~~~~~~~~~~~~~~~~~~~~^
        **{api_settings.USER_ID_FIELD: user_id}
        ^^^^^^^^^^^^^^^^^^^^^^^^^^^^^^^^^^^^^^^
    )
    ^
  File "C:\Users\Acer\AppData\Roaming\Python\Python313\site-packages\django\db\models\manager.py", line 87, in manager_method
    return getattr(self.get_queryset(), name)(*args, **kwargs)
           ~~~~~~~~~~~~~~~~~~~~~~~~~~~~~~~~~~^^^^^^^^^^^^^^^^^
  File "C:\Users\Acer\AppData\Roaming\Python\Python313\site-packages\django\db\models\query.py", line 633, in get
    raise self.model.DoesNotExist(
        "%s matching query does not exist." % self.model._meta.object_name
    )
django.contrib.auth.models.User.DoesNotExist: User matching query does not exist.
ERROR 2025-10-02 11:14:52,695 basehttp "POST /api/auth/refresh/ HTTP/1.1" 500 124283
ERROR 2025-10-02 11:14:52,695 basehttp "POST /api/auth/refresh/ HTTP/1.1" 500 124283
ERROR 2025-10-02 11:14:52,696 basehttp "POST /api/auth/refresh/ HTTP/1.1" 500 124283
ERROR 2025-10-02 11:14:52,696 basehttp "POST /api/auth/refresh/ HTTP/1.1" 500 124283
