ERROR 2025-10-02 11:14:52,684 log Internal Server Error: /api/auth/refresh/
Traceback (most recent call last):
  File "C:\Users\Acer\AppData\Roaming\Python\Python313\site-packages\django\core\handlers\exception.py", line 55, in inner
    response = get_response(request)
  File "C:\Users\Acer\AppData\Roaming\Python\Python313\site-packages\django\core\handlers\base.py", line 197, in _get_response
    response = wrapped_callback(request, *callback_args, **callback_kwargs)
  File "C:\Users\Acer\AppData\Roaming\Python\Python313\site-packages\django\views\decorators\csrf.py", line 65, in _view_wrapper
    return view_func(request, *args, **kwargs)
  File "C:\Users\Acer\AppData\Roaming\Python\Python313\site-packages\django\views\generic\base.py", line 105, in view
    return self.dispatch(request, *args, **kwargs)
           ~~~~~~~~~~~~~^^^^^^^^^^^^^^^^^^^^^^^^^^
  File "C:\Users\Acer\AppData\Roaming\Python\Python313\site-packages\rest_framework\views.py", line 515, in dispatch
    response = self.handle_exception(exc)
  File "C:\Users\Acer\AppData\Roaming\Python\Python313\site-packages\rest_framework\views.py", line 475, in handle_exception
    self.raise_uncaught_exception(exc)
    ~~~~~~~~~~~~~~~~~~~~~~~~~~~~~^^^^^
  File "C:\Users\Acer\AppData\Roaming\Python\Python313\site-packages\rest_framework\views.py", line 486, in raise_uncaught_exception
    raise exc
  File "C:\Users\Acer\AppData\Roaming\Python\Python313\site-packages\rest_framework\views.py", line 512, in dispatch
    response = handler(request, *args, **kwargs)
  File "C:\Users\Acer\AppData\Roaming\Python\Python313\site-packages\rest_framework_simplejwt\views.py", line 46, in post
    serializer.is_valid(raise_exception=True)
    ~~~~~~~~~~~~~~~~~~~^^^^^^^^^^^^^^^^^^^^^^
  File "C:\Users\Acer\AppData\Roaming\Python\Python313\site-packages\rest_framework\serializers.py", line 225, in is_valid
    self._validated_data = self.run_validation(self.initial_data)
                           ~~~~~~~~~~~~~~~~~~~^^^^^^^^^^^^^^^^^^^
  File "C:\Users\Acer\AppData\Roaming\Python\Python313\site-packages\rest_framework\serializers.py", line 447, in run_validation
    value = self.validate(value)
  File "C:\Users\Acer\AppData\Roaming\Python\Python313\site-packages\rest_framework_simplejwt\serializers.py", line 116, in validate
    user := get_user_model().objects.get(
            ~~~~~~~~~~~~~~~~~~~~~~~~~~~~^
        **{api_settings.USER_ID_FIELD: user_id}
        ^^^^^^^^^^^^^^^^^^^^^^^^^^^^^^^^^^^^^^^
    )
    ^
  File "C:\Users\Acer\AppData\Roaming\Python\Python313\site-packages\django\db\models\manager.py", line 87, in manager_method
    return getattr(self.get_queryset(), name)(*args, **kwargs)
           ~~~~~~~~~~~~~~~~~~~~~~~~~~~~~~~~~~^^^^^^^^^^^^^^^^^
  File "C:\Users\Acer\AppData\Roaming\Python\Python313\site-packages\django\db\models\query.py", line 633, in get
    raise self.model.DoesNotExist(
        "%s matching query does not exist." % self.model._meta.object_name
    )
django.contrib.auth.models.User.DoesNotExist: User matching query does not exist.
ERROR 2025-10-02 11:14:52,685 log Internal Server Error: /api/auth/refresh/
Traceback (most recent call last):
  File "C:\Users\Acer\AppData\Roaming\Python\Python313\site-packages\django\core\handlers\exception.py", line 55, in inner
    response = get_response(request)
  File "C:\Users\Acer\AppData\Roaming\Python\Python313\site-packages\django\core\handlers\base.py", line 197, in _get_response
    response = wrapped_callback(request, *callback_args, **callback_kwargs)
  File "C:\Users\Acer\AppData\Roaming\Python\Python313\site-packages\django\views\decorators\csrf.py", line 65, in _view_wrapper
    return view_func(request, *args, **kwargs)
  File "C:\Users\Acer\AppData\Roaming\Python\Python313\site-packages\django\views\generic\base.py", line 105, in view
    return self.dispatch(request, *args, **kwargs)
           ~~~~~~~~~~~~~^^^^^^^^^^^^^^^^^^^^^^^^^^
  File "C:\Users\Acer\AppData\Roaming\Python\Python313\site-packages\rest_framework\views.py", line 515, in dispatch
    response = self.handle_exception(exc)
  File "C:\Users\Acer\AppData\Roaming\Python\Python313\site-packages\rest_framework\views.py", line 475, in handle_exception
    self.raise_uncaught_exception(exc)
    ~~~~~~~~~~~~~~~~~~~~~~~~~~~~~^^^^^
  File "C:\Users\Acer\AppData\Roaming\Python\Python313\site-packages\rest_framework\views.py", line 486, in raise_uncaught_exception
    raise exc
  File "C:\Users\Acer\AppData\Roaming\Python\Python313\site-packages\rest_framework\views.py", line 512, in dispatch
    response = handler(request, *args, **kwargs)
  File "C:\Users\Acer\AppData\Roaming\Python\Python313\site-packages\rest_framework_simplejwt\views.py", line 46, in post
    serializer.is_valid(raise_exception=True)
    ~~~~~~~~~~~~~~~~~~~^^^^^^^^^^^^^^^^^^^^^^
  File "C:\Users\Acer\AppData\Roaming\Python\Python313\site-packages\rest_framework\serializers.py", line 225, in is_valid
    self._validated_data = self.run_validation(self.initial_data)
                           ~~~~~~~~~~~~~~~~~~~^^^^^^^^^^^^^^^^^^^
  File "C:\Users\Acer\AppData\Roaming\Python\Python313\site-packages\rest_framework\serializers.py", line 447, in run_validation
    value = self.validate(value)
  File "C:\Users\Acer\AppData\Roaming\Python\Python313\site-packages\rest_framework_simplejwt\serializers.py", line 116, in validate
    user := get_user_model().objects.get(
            ~~~~~~~~~~~~~~~~~~~~~~~~~~~~^
        **{api_settings.USER_ID_FIELD: user_id}
        ^^^^^^^^^^^^^^^^^^^^^^^^^^^^^^^^^^^^^^^
    )
    ^
  File "C:\Users\Acer\AppData\Roaming\Python\Python313\site-packages\django\db\models\manager.py", line 87, in manager_method
    return getattr(self.get_queryset(), name)(*args, **kwargs)
           ~~~~~~~~~~~~~~~~~~~~~~~~~~~~~~~~~~^^^^^^^^^^^^^^^^^
  File "C:\Users\Acer\AppData\Roaming\Python\Python313\site-packages\django\db\models\query.py", line 633, in get
    raise self.model.DoesNotExist(
        "%s matching query does not exist." % self.model._meta.object_name
    )
django.contrib.auth.models.User.DoesNotExist: User matching query does not exist.
ERROR 2025-10-02 11:14:52,695 basehttp "POST /api/auth/refresh/ HTTP/1.1" 500 124283
ERROR 2025-10-02 11:14:52,695 basehttp "POST /api/auth/refresh/ HTTP/1.1" 500 124283
ERROR 2025-10-02 11:14:52,696 basehttp "POST /api/auth/refresh/ HTTP/1.1" 500 124283
ERROR 2025-10-02 11:14:52,696 basehttp "POST /api/auth/refresh/ HTTP/1.1" 500 124283
ERROR 2025-10-07 14:41:14,383 log Internal Server Error: /api/sentence_formation/story/activity/log/
ERROR 2025-10-07 14:41:14,392 basehttp "POST /api/sentence_formation/story/activity/log/ HTTP/1.1" 500 123
ERROR 2025-10-07 14:41:14,392 basehttp "POST /api/sentence_formation/story/activity/log/ HTTP/1.1" 500 123
ERROR 2025-10-07 14:41:15,972 log Internal Server Error: /api/sentence_formation/story/activity/log/
ERROR 2025-10-07 14:41:15,973 log Internal Server Error: /api/sentence_formation/story/activity/log/
ERROR 2025-10-07 14:41:15,973 basehttp "POST /api/sentence_formation/story/activity/log/ HTTP/1.1" 500 243
ERROR 2025-10-07 14:41:15,973 basehttp "POST /api/sentence_formation/story/activity/log/ HTTP/1.1" 500 243
ERROR 2025-10-07 14:41:15,973 basehttp "POST /api/sentence_formation/story/activity/log/ HTTP/1.1" 500 243
ERROR 2025-10-07 14:41:15,973 basehttp "POST /api/sentence_formation/story/activity/log/ HTTP/1.1" 500 243
ERROR 2025-10-07 14:44:05,695 log Internal Server Error: /api/sentence_formation/story/activity/log/
ERROR 2025-10-07 14:44:05,696 basehttp "POST /api/sentence_formation/story/activity/log/ HTTP/1.1" 500 119
ERROR 2025-10-07 14:44:05,696 basehttp "POST /api/sentence_formation/story/activity/log/ HTTP/1.1" 500 119
ERROR 2025-10-07 14:44:34,184 log Internal Server Error: /api/sentence_formation/story/activity/log/
ERROR 2025-10-07 14:44:34,185 basehttp "POST /api/sentence_formation/story/activity/log/ HTTP/1.1" 500 120
ERROR 2025-10-07 14:44:34,185 basehttp "POST /api/sentence_formation/story/activity/log/ HTTP/1.1" 500 120
ERROR 2025-10-07 14:44:40,932 log Internal Server Error: /api/sentence_formation/story/activity/log/
ERROR 2025-10-07 14:44:40,933 basehttp "POST /api/sentence_formation/story/activity/log/ HTTP/1.1" 500 119
ERROR 2025-10-07 14:44:40,933 basehttp "POST /api/sentence_formation/story/activity/log/ HTTP/1.1" 500 119
ERROR 2025-10-07 14:44:43,334 log Internal Server Error: /api/sentence_formation/story/activity/log/
ERROR 2025-10-07 14:44:43,335 basehttp "POST /api/sentence_formation/story/activity/log/ HTTP/1.1" 500 119
ERROR 2025-10-07 14:44:43,335 basehttp "POST /api/sentence_formation/story/activity/log/ HTTP/1.1" 500 119
ERROR 2025-10-07 14:44:46,155 log Internal Server Error: /api/sentence_formation/story/activity/log/
ERROR 2025-10-07 14:44:46,155 basehttp "POST /api/sentence_formation/story/activity/log/ HTTP/1.1" 500 118
ERROR 2025-10-07 14:44:46,155 basehttp "POST /api/sentence_formation/story/activity/log/ HTTP/1.1" 500 118
ERROR 2025-10-07 14:44:49,058 log Internal Server Error: /api/sentence_formation/story/activity/log/
ERROR 2025-10-07 14:44:49,058 basehttp "POST /api/sentence_formation/story/activity/log/ HTTP/1.1" 500 120
ERROR 2025-10-07 14:44:49,058 basehttp "POST /api/sentence_formation/story/activity/log/ HTTP/1.1" 500 120
ERROR 2025-10-07 14:44:51,702 log Internal Server Error: /api/sentence_formation/story/activity/log/
ERROR 2025-10-07 14:44:51,703 basehttp "POST /api/sentence_formation/story/activity/log/ HTTP/1.1" 500 118
ERROR 2025-10-07 14:44:51,703 basehttp "POST /api/sentence_formation/story/activity/log/ HTTP/1.1" 500 118
ERROR 2025-10-07 14:44:53,533 log Internal Server Error: /api/sentence_formation/story/activity/log/
ERROR 2025-10-07 14:44:53,534 basehttp "POST /api/sentence_formation/story/activity/log/ HTTP/1.1" 500 119
ERROR 2025-10-07 14:44:53,534 basehttp "POST /api/sentence_formation/story/activity/log/ HTTP/1.1" 500 119
ERROR 2025-10-07 14:44:55,172 log Internal Server Error: /api/sentence_formation/story/activity/log/
ERROR 2025-10-07 14:44:55,173 log Internal Server Error: /api/sentence_formation/story/activity/log/
ERROR 2025-10-07 14:44:55,173 basehttp "POST /api/sentence_formation/story/activity/log/ HTTP/1.1" 500 1144
ERROR 2025-10-07 14:44:55,173 basehttp "POST /api/sentence_formation/story/activity/log/ HTTP/1.1" 500 1144
ERROR 2025-10-07 14:44:55,173 basehttp "POST /api/sentence_formation/story/activity/log/ HTTP/1.1" 500 1144
ERROR 2025-10-07 14:44:55,173 basehttp "POST /api/sentence_formation/story/activity/log/ HTTP/1.1" 500 1144
ERROR 2025-10-07 14:50:12,321 log Internal Server Error: /api/sentence_formation/story/activity/log/
ERROR 2025-10-07 14:50:12,322 basehttp "POST /api/sentence_formation/story/activity/log/ HTTP/1.1" 500 119
ERROR 2025-10-07 14:50:12,322 basehttp "POST /api/sentence_formation/story/activity/log/ HTTP/1.1" 500 119
ERROR 2025-10-07 14:50:30,081 log Internal Server Error: /api/sentence_formation/story/activity/log/
ERROR 2025-10-07 14:50:30,081 basehttp "POST /api/sentence_formation/story/activity/log/ HTTP/1.1" 500 118
ERROR 2025-10-07 14:50:30,081 basehttp "POST /api/sentence_formation/story/activity/log/ HTTP/1.1" 500 118
ERROR 2025-10-07 14:50:42,716 log Internal Server Error: /api/sentence_formation/story/activity/log/
ERROR 2025-10-07 14:50:42,716 basehttp "POST /api/sentence_formation/story/activity/log/ HTTP/1.1" 500 118
ERROR 2025-10-07 14:50:42,716 basehttp "POST /api/sentence_formation/story/activity/log/ HTTP/1.1" 500 118
ERROR 2025-10-07 14:50:45,082 log Internal Server Error: /api/sentence_formation/story/activity/log/
ERROR 2025-10-07 14:50:45,082 basehttp "POST /api/sentence_formation/story/activity/log/ HTTP/1.1" 500 120
ERROR 2025-10-07 14:50:45,082 basehttp "POST /api/sentence_formation/story/activity/log/ HTTP/1.1" 500 120
ERROR 2025-10-07 14:50:47,125 log Internal Server Error: /api/sentence_formation/story/activity/log/
ERROR 2025-10-07 14:50:47,125 basehttp "POST /api/sentence_formation/story/activity/log/ HTTP/1.1" 500 119
ERROR 2025-10-07 14:50:47,125 basehttp "POST /api/sentence_formation/story/activity/log/ HTTP/1.1" 500 119
ERROR 2025-10-07 14:50:48,602 log Internal Server Error: /api/sentence_formation/story/activity/log/
ERROR 2025-10-07 14:50:48,603 basehttp "POST /api/sentence_formation/story/activity/log/ HTTP/1.1" 500 756
ERROR 2025-10-07 14:50:48,603 basehttp "POST /api/sentence_formation/story/activity/log/ HTTP/1.1" 500 756
ERROR 2025-10-07 14:50:48,724 log Internal Server Error: /api/sentence_formation/story/activity/log/
ERROR 2025-10-07 14:50:48,725 basehttp "POST /api/sentence_formation/story/activity/log/ HTTP/1.1" 500 756
ERROR 2025-10-07 14:50:48,725 basehttp "POST /api/sentence_formation/story/activity/log/ HTTP/1.1" 500 756
ERROR 2025-10-07 15:02:18,820 log Internal Server Error: /api/sentence_formation/story/analytics/
ERROR 2025-10-07 15:02:18,821 basehttp "GET /api/sentence_formation/story/analytics/?days=30&limit=50 HTTP/1.1" 500 67
ERROR 2025-10-07 15:02:18,821 basehttp "GET /api/sentence_formation/story/analytics/?days=30&limit=50 HTTP/1.1" 500 67
ERROR 2025-10-07 15:02:19,012 log Internal Server Error: /api/sentence_formation/story/analytics/
ERROR 2025-10-07 15:02:19,013 basehttp "GET /api/sentence_formation/story/analytics/?days=30&limit=50 HTTP/1.1" 500 67
ERROR 2025-10-07 15:02:19,013 basehttp "GET /api/sentence_formation/story/analytics/?days=30&limit=50 HTTP/1.1" 500 67
ERROR 2025-10-07 15:02:26,281 log Internal Server Error: /api/sentence_formation/story/analytics/
ERROR 2025-10-07 15:02:26,281 basehttp "GET /api/sentence_formation/story/analytics/?days=30&limit=50 HTTP/1.1" 500 67
ERROR 2025-10-07 15:02:26,281 basehttp "GET /api/sentence_formation/story/analytics/?days=30&limit=50 HTTP/1.1" 500 67
ERROR 2025-10-07 15:02:26,450 log Internal Server Error: /api/sentence_formation/story/analytics/
ERROR 2025-10-07 15:02:26,450 basehttp "GET /api/sentence_formation/story/analytics/?days=30&limit=50 HTTP/1.1" 500 67
ERROR 2025-10-07 15:02:26,450 basehttp "GET /api/sentence_formation/story/analytics/?days=30&limit=50 HTTP/1.1" 500 67
ERROR 2025-10-07 15:05:04,928 log Internal Server Error: /api/sentence_formation/story/analytics/
ERROR 2025-10-07 15:05:04,929 basehttp "GET /api/sentence_formation/story/analytics/?days=30&limit=50 HTTP/1.1" 500 67
ERROR 2025-10-07 15:05:04,929 basehttp "GET /api/sentence_formation/story/analytics/?days=30&limit=50 HTTP/1.1" 500 67
ERROR 2025-10-07 15:05:05,053 log Internal Server Error: /api/sentence_formation/story/analytics/
ERROR 2025-10-07 15:05:05,054 basehttp "GET /api/sentence_formation/story/analytics/?days=30&limit=50 HTTP/1.1" 500 67
ERROR 2025-10-07 15:05:05,054 basehttp "GET /api/sentence_formation/story/analytics/?days=30&limit=50 HTTP/1.1" 500 67
ERROR 2025-10-07 21:22:40,690 log Internal Server Error: /api/sentence_formation/story/analytics/
ERROR 2025-10-07 21:22:40,691 basehttp "GET /api/sentence_formation/story/analytics/?days=30&limit=50 HTTP/1.1" 500 67
ERROR 2025-10-07 21:22:40,691 basehttp "GET /api/sentence_formation/story/analytics/?days=30&limit=50 HTTP/1.1" 500 67
ERROR 2025-10-07 21:22:40,908 log Internal Server Error: /api/sentence_formation/story/analytics/
ERROR 2025-10-07 21:22:40,909 basehttp "GET /api/sentence_formation/story/analytics/?days=30&limit=50 HTTP/1.1" 500 67
ERROR 2025-10-07 21:22:40,909 basehttp "GET /api/sentence_formation/story/analytics/?days=30&limit=50 HTTP/1.1" 500 67
ERROR 2025-10-07 21:55:37,213 log Internal Server Error: /api/sentence_formation/story/activity/log/
ERROR 2025-10-07 21:55:37,214 basehttp "POST /api/sentence_formation/story/activity/log/ HTTP/1.1" 500 124
ERROR 2025-10-07 21:55:37,214 basehttp "POST /api/sentence_formation/story/activity/log/ HTTP/1.1" 500 124
ERROR 2025-10-07 21:55:48,460 log Internal Server Error: /api/sentence_formation/story/activity/log/
ERROR 2025-10-07 21:55:48,460 basehttp "POST /api/sentence_formation/story/activity/log/ HTTP/1.1" 500 123
ERROR 2025-10-07 21:55:48,460 basehttp "POST /api/sentence_formation/story/activity/log/ HTTP/1.1" 500 123
ERROR 2025-10-15 14:32:46,861 log Internal Server Error: /api/sentence_formation/story/analytics/
ERROR 2025-10-15 14:32:46,861 log Internal Server Error: /api/sentence_formation/story/analytics/
ERROR 2025-10-15 14:32:46,862 basehttp "GET /api/sentence_formation/story/analytics/?user_email=kenjiermita2020@gmail.com&days=30&_t=1760509965127 HTTP/1.1" 500 67
ERROR 2025-10-15 14:32:46,862 basehttp "GET /api/sentence_formation/story/analytics/?user_email=kenjiermita2020@gmail.com&days=30&_t=1760509965126 HTTP/1.1" 500 67
ERROR 2025-10-15 14:32:46,862 basehttp "GET /api/sentence_formation/story/analytics/?user_email=kenjiermita2020@gmail.com&days=30&_t=1760509965126 HTTP/1.1" 500 67
ERROR 2025-10-15 14:32:46,862 basehttp "GET /api/sentence_formation/story/analytics/?user_email=kenjiermita2020@gmail.com&days=30&_t=1760509965127 HTTP/1.1" 500 67
ERROR 2025-10-15 14:32:47,506 log Internal Server Error: /api/sentence_formation/story/analytics/
ERROR 2025-10-15 14:32:47,507 basehttp "GET /api/sentence_formation/story/analytics/?user_email=kenjiermita2020@gmail.com&days=30 HTTP/1.1" 500 67
ERROR 2025-10-15 14:32:47,507 basehttp "GET /api/sentence_formation/story/analytics/?user_email=kenjiermita2020@gmail.com&days=30 HTTP/1.1" 500 67
ERROR 2025-10-15 14:32:51,495 log Internal Server Error: /api/sentence_formation/story/analytics/
ERROR 2025-10-15 14:32:51,496 log Internal Server Error: /api/sentence_formation/story/analytics/
ERROR 2025-10-15 14:32:51,496 basehttp "GET /api/sentence_formation/story/analytics/?user_email=kenjiermita2020@gmail.com&days=30&_t=1760509971121 HTTP/1.1" 500 67
ERROR 2025-10-15 14:32:51,496 basehttp "GET /api/sentence_formation/story/analytics/?user_email=kenjiermita2020@gmail.com&days=30&_t=1760509971121 HTTP/1.1" 500 67
ERROR 2025-10-15 14:32:51,497 basehttp "GET /api/sentence_formation/story/analytics/?user_email=kenjiermita2020@gmail.com&days=30&_t=1760509971122 HTTP/1.1" 500 67
ERROR 2025-10-15 14:32:51,497 basehttp "GET /api/sentence_formation/story/analytics/?user_email=kenjiermita2020@gmail.com&days=30&_t=1760509971122 HTTP/1.1" 500 67
ERROR 2025-10-15 14:33:30,787 log Internal Server Error: /api/sentence_formation/story/analytics/
ERROR 2025-10-15 14:33:30,787 basehttp "GET /api/sentence_formation/story/analytics/?user_email=kenjiermita2020@gmail.com&days=30&_t=1760510010048 HTTP/1.1" 500 67
ERROR 2025-10-15 14:33:30,787 basehttp "GET /api/sentence_formation/story/analytics/?user_email=kenjiermita2020@gmail.com&days=30&_t=1760510010048 HTTP/1.1" 500 67
ERROR 2025-10-15 14:33:31,103 log Internal Server Error: /api/sentence_formation/story/analytics/
ERROR 2025-10-15 14:33:31,104 basehttp "GET /api/sentence_formation/story/analytics/?user_email=kenjiermita2020@gmail.com&days=30&_t=1760510010048 HTTP/1.1" 500 67
ERROR 2025-10-15 14:33:31,104 basehttp "GET /api/sentence_formation/story/analytics/?user_email=kenjiermita2020@gmail.com&days=30&_t=1760510010048 HTTP/1.1" 500 67
ERROR 2025-10-15 14:33:31,410 log Internal Server Error: /api/sentence_formation/story/analytics/
ERROR 2025-10-15 14:33:31,410 basehttp "GET /api/sentence_formation/story/analytics/?user_email=kenjiermita2020@gmail.com&days=30&_t=1760510010048 HTTP/1.1" 500 67
ERROR 2025-10-15 14:33:31,410 basehttp "GET /api/sentence_formation/story/analytics/?user_email=kenjiermita2020@gmail.com&days=30&_t=1760510010048 HTTP/1.1" 500 67
ERROR 2025-10-15 14:33:31,715 log Internal Server Error: /api/sentence_formation/story/analytics/
ERROR 2025-10-15 14:33:31,715 basehttp "GET /api/sentence_formation/story/analytics/?user_email=kenjiermita2020@gmail.com&days=30&_t=1760510010048 HTTP/1.1" 500 67
ERROR 2025-10-15 14:33:31,715 basehttp "GET /api/sentence_formation/story/analytics/?user_email=kenjiermita2020@gmail.com&days=30&_t=1760510010048 HTTP/1.1" 500 67
ERROR 2025-10-15 15:02:24,156 log Internal Server Error: /api/sentence_formation/story/activity/log/
ERROR 2025-10-15 15:02:24,157 basehttp "POST /api/sentence_formation/story/activity/log/ HTTP/1.1" 500 42
ERROR 2025-10-15 15:02:24,157 basehttp "POST /api/sentence_formation/story/activity/log/ HTTP/1.1" 500 42
ERROR 2025-10-16 00:41:12,296 services_ai Error uploading to Supabase Storage: {'statusCode': 403, 'error': Unauthorized, 'message': new row violates row-level security policy}
ERROR 2025-10-16 00:41:12,296 views Error uploading image: Upload failed: {'statusCode': 403, 'error': Unauthorized, 'message': new row violates row-level security policy}
ERROR 2025-10-16 00:41:13,128 services_ai Error uploading to Supabase Storage: {'statusCode': 403, 'error': Unauthorized, 'message': new row violates row-level security policy}
ERROR 2025-10-16 00:41:13,128 views Error uploading full word audio: Upload failed: {'statusCode': 403, 'error': Unauthorized, 'message': new row violates row-level security policy}
ERROR 2025-10-16 00:41:13,882 services_ai Error uploading to Supabase Storage: {'statusCode': 403, 'error': Unauthorized, 'message': new row violates row-level security policy}
ERROR 2025-10-16 00:41:13,882 views Error uploading syllable audio 0: Upload failed: {'statusCode': 403, 'error': Unauthorized, 'message': new row violates row-level security policy}
ERROR 2025-10-16 00:47:39,336 services_ai Error uploading to Supabase Storage: {'statusCode': 403, 'error': Unauthorized, 'message': new row violates row-level security policy}
ERROR 2025-10-16 00:47:39,336 views Error uploading image: Upload failed: {'statusCode': 403, 'error': Unauthorized, 'message': new row violates row-level security policy}
ERROR 2025-10-16 00:47:40,079 services_ai Error uploading to Supabase Storage: {'statusCode': 403, 'error': Unauthorized, 'message': new row violates row-level security policy}
ERROR 2025-10-16 00:47:40,080 views Error uploading full word audio: Upload failed: {'statusCode': 403, 'error': Unauthorized, 'message': new row violates row-level security policy}
ERROR 2025-10-16 00:47:40,817 services_ai Error uploading to Supabase Storage: {'statusCode': 403, 'error': Unauthorized, 'message': new row violates row-level security policy}
ERROR 2025-10-16 00:47:40,817 views Error uploading syllable audio 0: Upload failed: {'statusCode': 403, 'error': Unauthorized, 'message': new row violates row-level security policy}
ERROR 2025-10-16 01:02:35,102 services_ai    Exception type: StorageApiError
ERROR 2025-10-16 01:02:35,102 views Error uploading image 'frog.jpg': Permission denied when uploading to 'syllable-word-images'. Check Supabase storage policies.
ERROR 2025-10-16 01:02:36,233 services_ai    Exception type: StorageApiError
ERROR 2025-10-16 01:02:36,233 views Error uploading full word audio 'frog_full.mp3': Permission denied when uploading to 'syllable-word-audio'. Check Supabase storage policies.
ERROR 2025-10-16 01:02:36,926 services_ai    Exception type: StorageApiError
ERROR 2025-10-16 01:02:36,926 views Error uploading syllable audio 0: Permission denied when uploading to 'syllable-word-audio'. Check Supabase storage policies.
ERROR 2025-10-16 01:11:00,947 services_ai    Exception type: StorageApiError
ERROR 2025-10-16 01:11:00,947 views Error uploading image 'frog.jpg': Permission denied when uploading to 'syllable-word-images'. Check Supabase storage policies.
ERROR 2025-10-16 01:14:42,908 services_ai    Exception type: StorageApiError
ERROR 2025-10-16 01:14:42,908 views Error uploading image 'frog.jpg': Permission denied when uploading to 'syllable-word-images'. Check Supabase storage policies.
ERROR 2025-10-16 01:14:44,049 services_ai    Exception type: StorageApiError
ERROR 2025-10-16 01:14:44,049 views Error uploading full word audio 'frog_full.mp3': Permission denied when uploading to 'syllable-word-audio'. Check Supabase storage policies.
ERROR 2025-10-16 01:14:44,835 services_ai    Exception type: StorageApiError
ERROR 2025-10-16 01:14:44,835 views Error uploading syllable audio 0: Permission denied when uploading to 'syllable-word-audio'. Check Supabase storage policies.
ERROR 2025-10-16 01:14:45,164 views Traceback (most recent call last):
  File "C:\Users\GAMING\Documents\GitHub\WildLitz-Capstone\backend\wildlitz\syllabification\views.py", line 639, in create_custom_word
    }).execute()
       ~~~~~~~^^
  File "C:\Users\GAMING\Documents\GitHub\WildLitz-Capstone\capstone\Lib\site-packages\postgrest\_sync\request_builder.py", line 126, in execute
    raise APIError(dict(json_obj))
postgrest.exceptions.APIError: {'message': 'duplicate key value violates unique constraint "unique_word"', 'code': '23505', 'hint': None, 'details': 'Key (word)=(frog) already exists.'}

ERROR 2025-10-16 01:18:23,559 services_ai    Exception type: StorageApiError
ERROR 2025-10-16 01:18:23,559 views Error uploading image 'frog.jpg': Permission denied when uploading to 'syllable-word-images'. Check Supabase storage policies.
ERROR 2025-10-16 01:18:24,272 services_ai    Exception type: StorageApiError
ERROR 2025-10-16 01:18:24,272 views Error uploading full word audio 'frog_full.mp3': Permission denied when uploading to 'syllable-word-audio'. Check Supabase storage policies.
ERROR 2025-10-16 01:18:25,227 services_ai    Exception type: StorageApiError
ERROR 2025-10-16 01:18:25,227 views Error uploading syllable audio 0: Permission denied when uploading to 'syllable-word-audio'. Check Supabase storage policies.
ERROR 2025-10-16 01:24:16,173 services_ai    Exception type: StorageApiError
ERROR 2025-10-16 01:24:16,173 views Error uploading image 'frog.jpg': Permission denied when uploading to 'syllable-word-images'. Check Supabase storage policies.
ERROR 2025-10-16 01:24:17,399 services_ai    Exception type: StorageApiError
ERROR 2025-10-16 01:24:17,399 views Error uploading full word audio 'frog_full.mp3': Permission denied when uploading to 'syllable-word-audio'. Check Supabase storage policies.
ERROR 2025-10-16 01:24:18,311 services_ai    Exception type: StorageApiError
ERROR 2025-10-16 01:24:18,311 views Error uploading syllable audio 0: Permission denied when uploading to 'syllable-word-audio'. Check Supabase storage policies.
ERROR 2025-10-16 01:29:47,818 services_ai    Exception type: StorageApiError
ERROR 2025-10-16 01:29:47,818 views Error uploading image 'butterfly.jpg': Permission denied when uploading to 'syllable-word-images'. Check Supabase storage policies.
ERROR 2025-10-16 01:38:40,783 services_ai    Exception type: StorageApiError
ERROR 2025-10-16 01:38:40,783 views Error uploading image 'butterfly.jpg': Permission denied when uploading to 'syllable-word-images'. Check Supabase storage policies.
ERROR 2025-10-16 01:38:41,794 services_ai    Exception type: StorageApiError
ERROR 2025-10-16 01:38:41,795 views Error uploading full word audio 'butterfly_full.mp3': Permission denied when uploading to 'syllable-word-audio'. Check Supabase storage policies.
ERROR 2025-10-16 01:38:42,451 services_ai    Exception type: StorageApiError
ERROR 2025-10-16 01:38:42,451 views Error uploading syllable audio 0: Permission denied when uploading to 'syllable-word-audio'. Check Supabase storage policies.
ERROR 2025-10-16 01:38:43,774 services_ai    Exception type: StorageApiError
ERROR 2025-10-16 01:38:43,774 views Error uploading syllable audio 1: Permission denied when uploading to 'syllable-word-audio'. Check Supabase storage policies.
ERROR 2025-10-16 01:38:44,471 services_ai    Exception type: StorageApiError
ERROR 2025-10-16 01:38:44,471 views Error uploading syllable audio 2: Permission denied when uploading to 'syllable-word-audio'. Check Supabase storage policies.
ERROR 2025-10-16 01:42:16,769 services_ai    Exception type: StorageApiError
ERROR 2025-10-16 01:42:16,770 views Error uploading image 'tiger.jpg': Permission denied when uploading to 'syllable-word-images'. Check Supabase storage policies.
ERROR 2025-10-16 01:56:44,414 views Traceback (most recent call last):
  File "C:\Users\GAMING\Documents\GitHub\WildLitz-Capstone\backend\wildlitz\syllabification\views.py", line 534, in create_custom_word
    timestamp = datetime.now().strftime('%Y%m%d_%H%M%S')
                ^^^^^^^^
NameError: name 'datetime' is not defined. Did you forget to import 'datetime'?

ERROR 2025-10-26 22:47:50,330 views Error in get_my_progress_summary for user 7: unsupported operand type(s) for +: 'int' and 'datetime.timedelta'
ERROR 2025-10-26 22:47:50,336 log Internal Server Error: /api/syllabification/get-my-progress-summary/
ERROR 2025-10-26 22:47:50,341 basehttp "GET /api/syllabification/get-my-progress-summary/ HTTP/1.1" 500 77
ERROR 2025-10-26 22:47:50,341 basehttp "GET /api/syllabification/get-my-progress-summary/ HTTP/1.1" 500 77
ERROR 2025-10-26 22:47:50,378 views Error in get_my_progress_summary for user 7: unsupported operand type(s) for +: 'int' and 'datetime.timedelta'
ERROR 2025-10-26 22:47:50,379 log Internal Server Error: /api/syllabification/get-my-progress-summary/
ERROR 2025-10-26 22:47:50,381 basehttp "GET /api/syllabification/get-my-progress-summary/ HTTP/1.1" 500 77
ERROR 2025-10-26 22:47:50,381 basehttp "GET /api/syllabification/get-my-progress-summary/ HTTP/1.1" 500 77
ERROR 2025-10-26 22:48:45,839 views Error in get_my_progress_summary for user 7: unsupported operand type(s) for +: 'int' and 'datetime.timedelta'
ERROR 2025-10-26 22:48:45,841 log Internal Server Error: /api/syllabification/get-my-progress-summary/
ERROR 2025-10-26 22:48:45,842 basehttp "GET /api/syllabification/get-my-progress-summary/ HTTP/1.1" 500 77
ERROR 2025-10-26 22:48:45,842 basehttp "GET /api/syllabification/get-my-progress-summary/ HTTP/1.1" 500 77
ERROR 2025-10-26 22:48:45,877 views Error in get_my_progress_summary for user 7: unsupported operand type(s) for +: 'int' and 'datetime.timedelta'
ERROR 2025-10-26 22:48:45,879 log Internal Server Error: /api/syllabification/get-my-progress-summary/
ERROR 2025-10-26 22:48:45,880 basehttp "GET /api/syllabification/get-my-progress-summary/ HTTP/1.1" 500 77
ERROR 2025-10-26 22:48:45,880 basehttp "GET /api/syllabification/get-my-progress-summary/ HTTP/1.1" 500 77
ERROR 2025-10-26 22:51:44,430 views Error in get_my_progress_summary for user 7: unsupported operand type(s) for +: 'int' and 'datetime.timedelta'
ERROR 2025-10-26 22:51:44,436 log Internal Server Error: /api/syllabification/get-my-progress-summary/
ERROR 2025-10-26 22:51:44,437 basehttp "GET /api/syllabification/get-my-progress-summary/ HTTP/1.1" 500 77
ERROR 2025-10-26 22:51:44,437 basehttp "GET /api/syllabification/get-my-progress-summary/ HTTP/1.1" 500 77
ERROR 2025-10-26 22:51:44,473 views Error in get_my_progress_summary for user 7: unsupported operand type(s) for +: 'int' and 'datetime.timedelta'
ERROR 2025-10-26 22:51:44,476 log Internal Server Error: /api/syllabification/get-my-progress-summary/
ERROR 2025-10-26 22:51:44,488 basehttp "GET /api/syllabification/get-my-progress-summary/ HTTP/1.1" 500 77
ERROR 2025-10-26 22:51:44,488 basehttp "GET /api/syllabification/get-my-progress-summary/ HTTP/1.1" 500 77
ERROR 2025-10-26 22:54:41,983 views Error in get_my_progress_summary for user 7: unsupported operand type(s) for +: 'int' and 'datetime.timedelta'
ERROR 2025-10-26 22:54:41,984 log Internal Server Error: /api/syllabification/get-my-progress-summary/
ERROR 2025-10-26 22:54:41,985 basehttp "GET /api/syllabification/get-my-progress-summary/ HTTP/1.1" 500 77
ERROR 2025-10-26 22:54:41,985 basehttp "GET /api/syllabification/get-my-progress-summary/ HTTP/1.1" 500 77
ERROR 2025-10-26 22:54:42,017 views Error in get_my_progress_summary for user 7: unsupported operand type(s) for +: 'int' and 'datetime.timedelta'
ERROR 2025-10-26 22:54:42,020 log Internal Server Error: /api/syllabification/get-my-progress-summary/
ERROR 2025-10-26 22:54:42,023 basehttp "GET /api/syllabification/get-my-progress-summary/ HTTP/1.1" 500 77
ERROR 2025-10-26 22:54:42,023 basehttp "GET /api/syllabification/get-my-progress-summary/ HTTP/1.1" 500 77
ERROR 2025-10-26 23:44:13,976 views Failed to log activity for user 7: The `request` argument must be an instance of `django.http.HttpRequest`, not `rest_framework.request.Request`.
ERROR 2025-10-26 23:44:24,002 views Failed to log activity for user 7: The `request` argument must be an instance of `django.http.HttpRequest`, not `rest_framework.request.Request`.
ERROR 2025-10-26 23:44:33,647 views Failed to log activity for user 7: The `request` argument must be an instance of `django.http.HttpRequest`, not `rest_framework.request.Request`.
ERROR 2025-10-26 23:44:43,279 views Failed to log activity for user 7: The `request` argument must be an instance of `django.http.HttpRequest`, not `rest_framework.request.Request`.
ERROR 2025-10-26 23:44:53,365 views Failed to log activity for user 7: The `request` argument must be an instance of `django.http.HttpRequest`, not `rest_framework.request.Request`.
ERROR 2025-10-27 00:56:41,026 views Failed to log activity for user 7: The `request` argument must be an instance of `django.http.HttpRequest`, not `rest_framework.request.Request`.
ERROR 2025-10-27 00:56:52,938 views Failed to log activity for user 7: The `request` argument must be an instance of `django.http.HttpRequest`, not `rest_framework.request.Request`.
ERROR 2025-10-27 00:57:02,573 views Failed to log activity for user 7: The `request` argument must be an instance of `django.http.HttpRequest`, not `rest_framework.request.Request`.
ERROR 2025-10-27 00:57:18,426 views Failed to log activity for user 7: The `request` argument must be an instance of `django.http.HttpRequest`, not `rest_framework.request.Request`.
ERROR 2025-10-27 00:57:30,067 views Failed to log activity for user 7: The `request` argument must be an instance of `django.http.HttpRequest`, not `rest_framework.request.Request`.
ERROR 2025-10-27 00:57:39,863 views Failed to log activity for user 7: The `request` argument must be an instance of `django.http.HttpRequest`, not `rest_framework.request.Request`.
ERROR 2025-10-27 00:57:49,868 views Failed to log activity for user 7: The `request` argument must be an instance of `django.http.HttpRequest`, not `rest_framework.request.Request`.
ERROR 2025-10-27 00:58:03,748 views Failed to log activity for user 7: The `request` argument must be an instance of `django.http.HttpRequest`, not `rest_framework.request.Request`.
ERROR 2025-10-27 00:58:14,348 views Failed to log activity for user 7: The `request` argument must be an instance of `django.http.HttpRequest`, not `rest_framework.request.Request`.
ERROR 2025-10-27 00:58:38,832 views Failed to log activity for user 7: The `request` argument must be an instance of `django.http.HttpRequest`, not `rest_framework.request.Request`.
ERROR 2025-10-27 01:02:19,977 views Failed to log activity for user 7: The `request` argument must be an instance of `django.http.HttpRequest`, not `rest_framework.request.Request`.
ERROR 2025-10-27 01:02:30,039 views Failed to log activity for user 7: The `request` argument must be an instance of `django.http.HttpRequest`, not `rest_framework.request.Request`.
ERROR 2025-10-27 01:02:39,920 views Failed to log activity for user 7: The `request` argument must be an instance of `django.http.HttpRequest`, not `rest_framework.request.Request`.
ERROR 2025-10-27 01:02:50,587 views Failed to log activity for user 7: The `request` argument must be an instance of `django.http.HttpRequest`, not `rest_framework.request.Request`.
ERROR 2025-10-27 01:03:01,120 views Failed to log activity for user 7: The `request` argument must be an instance of `django.http.HttpRequest`, not `rest_framework.request.Request`.
ERROR 2025-10-27 01:04:55,698 views Failed to log activity for user 7: The `request` argument must be an instance of `django.http.HttpRequest`, not `rest_framework.request.Request`.
ERROR 2025-10-27 01:05:05,494 views Failed to log activity for user 7: The `request` argument must be an instance of `django.http.HttpRequest`, not `rest_framework.request.Request`.
ERROR 2025-10-27 01:05:16,213 views Failed to log activity for user 7: The `request` argument must be an instance of `django.http.HttpRequest`, not `rest_framework.request.Request`.
ERROR 2025-10-27 01:05:26,213 views Failed to log activity for user 7: The `request` argument must be an instance of `django.http.HttpRequest`, not `rest_framework.request.Request`.
ERROR 2025-10-27 01:05:37,391 views Failed to log activity for user 7: The `request` argument must be an instance of `django.http.HttpRequest`, not `rest_framework.request.Request`.
ERROR 2025-10-27 01:08:17,140 views Failed to log activity for user 7: The `request` argument must be an instance of `django.http.HttpRequest`, not `rest_framework.request.Request`.
ERROR 2025-10-27 01:08:27,566 views Failed to log activity for user 7: The `request` argument must be an instance of `django.http.HttpRequest`, not `rest_framework.request.Request`.
ERROR 2025-10-27 01:08:39,190 views Failed to log activity for user 7: The `request` argument must be an instance of `django.http.HttpRequest`, not `rest_framework.request.Request`.
ERROR 2025-10-27 01:08:49,223 views Failed to log activity for user 7: The `request` argument must be an instance of `django.http.HttpRequest`, not `rest_framework.request.Request`.
ERROR 2025-10-27 01:08:59,631 views Failed to log activity for user 7: The `request` argument must be an instance of `django.http.HttpRequest`, not `rest_framework.request.Request`.
ERROR 2025-10-27 01:16:38,414 log Internal Server Error: /api/get-my-progress-summary/
Traceback (most recent call last):
  File "C:\Github\WildLitz-Capstone\backend\wildlitz\api\views.py", line 272, in get_my_progress_summary
    total_time_spent_sec = sum(p.total_time_spent for p in progress_records)
TypeError: unsupported operand type(s) for +: 'int' and 'datetime.timedelta'

During handling of the above exception, another exception occurred:

Traceback (most recent call last):
  File "C:\Github\WildLitz-Capstone\venv\Lib\site-packages\django\core\handlers\exception.py", line 55, in inner
    response = get_response(request)
  File "C:\Github\WildLitz-Capstone\venv\Lib\site-packages\django\core\handlers\base.py", line 197, in _get_response
    response = wrapped_callback(request, *callback_args, **callback_kwargs)
  File "C:\Github\WildLitz-Capstone\venv\Lib\site-packages\django\views\decorators\csrf.py", line 65, in _view_wrapper
    return view_func(request, *args, **kwargs)
  File "C:\Github\WildLitz-Capstone\venv\Lib\site-packages\django\views\generic\base.py", line 105, in view
    return self.dispatch(request, *args, **kwargs)
           ~~~~~~~~~~~~~^^^^^^^^^^^^^^^^^^^^^^^^^^
  File "C:\Github\WildLitz-Capstone\venv\Lib\site-packages\rest_framework\views.py", line 515, in dispatch
    response = self.handle_exception(exc)
  File "C:\Github\WildLitz-Capstone\venv\Lib\site-packages\rest_framework\views.py", line 475, in handle_exception
    self.raise_uncaught_exception(exc)
    ~~~~~~~~~~~~~~~~~~~~~~~~~~~~~^^^^^
  File "C:\Github\WildLitz-Capstone\venv\Lib\site-packages\rest_framework\views.py", line 486, in raise_uncaught_exception
    raise exc
  File "C:\Github\WildLitz-Capstone\venv\Lib\site-packages\rest_framework\views.py", line 512, in dispatch
    response = handler(request, *args, **kwargs)
  File "C:\Github\WildLitz-Capstone\venv\Lib\site-packages\rest_framework\decorators.py", line 50, in handler
    return func(*args, **kwargs)
  File "C:\Github\WildLitz-Capstone\backend\wildlitz\api\views.py", line 288, in get_my_progress_summary
    logger.error(f"Error in get_my_progress_summary for user {user.id}: {str(e)}")
    ^^^^^^
NameError: name 'logger' is not defined
ERROR 2025-10-27 01:16:38,422 basehttp "GET /api/get-my-progress-summary/ HTTP/1.1" 500 111887
ERROR 2025-10-27 01:16:38,422 basehttp "GET /api/get-my-progress-summary/ HTTP/1.1" 500 111887
ERROR 2025-10-27 01:16:38,488 log Internal Server Error: /api/get-my-progress-summary/
Traceback (most recent call last):
  File "C:\Github\WildLitz-Capstone\backend\wildlitz\api\views.py", line 272, in get_my_progress_summary
    total_time_spent_sec = sum(p.total_time_spent for p in progress_records)
TypeError: unsupported operand type(s) for +: 'int' and 'datetime.timedelta'

During handling of the above exception, another exception occurred:

Traceback (most recent call last):
  File "C:\Github\WildLitz-Capstone\venv\Lib\site-packages\django\core\handlers\exception.py", line 55, in inner
    response = get_response(request)
  File "C:\Github\WildLitz-Capstone\venv\Lib\site-packages\django\core\handlers\base.py", line 197, in _get_response
    response = wrapped_callback(request, *callback_args, **callback_kwargs)
  File "C:\Github\WildLitz-Capstone\venv\Lib\site-packages\django\views\decorators\csrf.py", line 65, in _view_wrapper
    return view_func(request, *args, **kwargs)
  File "C:\Github\WildLitz-Capstone\venv\Lib\site-packages\django\views\generic\base.py", line 105, in view
    return self.dispatch(request, *args, **kwargs)
           ~~~~~~~~~~~~~^^^^^^^^^^^^^^^^^^^^^^^^^^
  File "C:\Github\WildLitz-Capstone\venv\Lib\site-packages\rest_framework\views.py", line 515, in dispatch
    response = self.handle_exception(exc)
  File "C:\Github\WildLitz-Capstone\venv\Lib\site-packages\rest_framework\views.py", line 475, in handle_exception
    self.raise_uncaught_exception(exc)
    ~~~~~~~~~~~~~~~~~~~~~~~~~~~~~^^^^^
  File "C:\Github\WildLitz-Capstone\venv\Lib\site-packages\rest_framework\views.py", line 486, in raise_uncaught_exception
    raise exc
  File "C:\Github\WildLitz-Capstone\venv\Lib\site-packages\rest_framework\views.py", line 512, in dispatch
    response = handler(request, *args, **kwargs)
  File "C:\Github\WildLitz-Capstone\venv\Lib\site-packages\rest_framework\decorators.py", line 50, in handler
    return func(*args, **kwargs)
  File "C:\Github\WildLitz-Capstone\backend\wildlitz\api\views.py", line 288, in get_my_progress_summary
    logger.error(f"Error in get_my_progress_summary for user {user.id}: {str(e)}")
    ^^^^^^
NameError: name 'logger' is not defined
ERROR 2025-10-27 01:16:38,493 basehttp "GET /api/get-my-progress-summary/ HTTP/1.1" 500 111887
ERROR 2025-10-27 01:16:38,493 basehttp "GET /api/get-my-progress-summary/ HTTP/1.1" 500 111887
ERROR 2025-10-27 01:19:42,769 log Internal Server Error: /api/get-my-progress-summary/
Traceback (most recent call last):
  File "C:\Github\WildLitz-Capstone\backend\wildlitz\api\views.py", line 273, in get_my_progress_summary
TypeError: unsupported operand type(s) for +: 'int' and 'datetime.timedelta'

During handling of the above exception, another exception occurred:

Traceback (most recent call last):
  File "C:\Github\WildLitz-Capstone\venv\Lib\site-packages\django\core\handlers\exception.py", line 55, in inner
    response = get_response(request)
  File "C:\Github\WildLitz-Capstone\venv\Lib\site-packages\django\core\handlers\base.py", line 197, in _get_response
    response = wrapped_callback(request, *callback_args, **callback_kwargs)
  File "C:\Github\WildLitz-Capstone\venv\Lib\site-packages\django\views\decorators\csrf.py", line 65, in _view_wrapper
    return view_func(request, *args, **kwargs)
  File "C:\Github\WildLitz-Capstone\venv\Lib\site-packages\django\views\generic\base.py", line 105, in view
    return self.dispatch(request, *args, **kwargs)
           ~~~~~~~~~~~~~^^^^^^^^^^^^^^^^^^^^^^^^^^
  File "C:\Github\WildLitz-Capstone\venv\Lib\site-packages\rest_framework\views.py", line 515, in dispatch
    response = self.handle_exception(exc)
  File "C:\Github\WildLitz-Capstone\venv\Lib\site-packages\rest_framework\views.py", line 475, in handle_exception
    self.raise_uncaught_exception(exc)
    ~~~~~~~~~~~~~~~~~~~~~~~~~~~~~^^^^^
  File "C:\Github\WildLitz-Capstone\venv\Lib\site-packages\rest_framework\views.py", line 486, in raise_uncaught_exception
    raise exc
  File "C:\Github\WildLitz-Capstone\venv\Lib\site-packages\rest_framework\views.py", line 512, in dispatch
    response = handler(request, *args, **kwargs)
  File "C:\Github\WildLitz-Capstone\venv\Lib\site-packages\rest_framework\decorators.py", line 50, in handler
    return func(*args, **kwargs)
  File "C:\Github\WildLitz-Capstone\backend\wildlitz\api\views.py", line 289, in get_my_progress_summary
NameError: name 'logger' is not defined
ERROR 2025-10-27 01:19:42,773 basehttp "GET /api/get-my-progress-summary/ HTTP/1.1" 500 108985
ERROR 2025-10-27 01:19:42,773 basehttp "GET /api/get-my-progress-summary/ HTTP/1.1" 500 108985
ERROR 2025-10-27 01:19:42,834 log Internal Server Error: /api/get-my-progress-summary/
Traceback (most recent call last):
  File "C:\Github\WildLitz-Capstone\backend\wildlitz\api\views.py", line 273, in get_my_progress_summary
TypeError: unsupported operand type(s) for +: 'int' and 'datetime.timedelta'

During handling of the above exception, another exception occurred:

Traceback (most recent call last):
  File "C:\Github\WildLitz-Capstone\venv\Lib\site-packages\django\core\handlers\exception.py", line 55, in inner
    response = get_response(request)
  File "C:\Github\WildLitz-Capstone\venv\Lib\site-packages\django\core\handlers\base.py", line 197, in _get_response
    response = wrapped_callback(request, *callback_args, **callback_kwargs)
  File "C:\Github\WildLitz-Capstone\venv\Lib\site-packages\django\views\decorators\csrf.py", line 65, in _view_wrapper
    return view_func(request, *args, **kwargs)
  File "C:\Github\WildLitz-Capstone\venv\Lib\site-packages\django\views\generic\base.py", line 105, in view
    return self.dispatch(request, *args, **kwargs)
           ~~~~~~~~~~~~~^^^^^^^^^^^^^^^^^^^^^^^^^^
  File "C:\Github\WildLitz-Capstone\venv\Lib\site-packages\rest_framework\views.py", line 515, in dispatch
    response = self.handle_exception(exc)
  File "C:\Github\WildLitz-Capstone\venv\Lib\site-packages\rest_framework\views.py", line 475, in handle_exception
    self.raise_uncaught_exception(exc)
    ~~~~~~~~~~~~~~~~~~~~~~~~~~~~~^^^^^
  File "C:\Github\WildLitz-Capstone\venv\Lib\site-packages\rest_framework\views.py", line 486, in raise_uncaught_exception
    raise exc
  File "C:\Github\WildLitz-Capstone\venv\Lib\site-packages\rest_framework\views.py", line 512, in dispatch
    response = handler(request, *args, **kwargs)
  File "C:\Github\WildLitz-Capstone\venv\Lib\site-packages\rest_framework\decorators.py", line 50, in handler
    return func(*args, **kwargs)
  File "C:\Github\WildLitz-Capstone\backend\wildlitz\api\views.py", line 289, in get_my_progress_summary
NameError: name 'logger' is not defined
ERROR 2025-10-27 01:19:42,836 basehttp "GET /api/get-my-progress-summary/ HTTP/1.1" 500 108985
ERROR 2025-10-27 01:19:42,836 basehttp "GET /api/get-my-progress-summary/ HTTP/1.1" 500 108985
ERROR 2025-10-27 01:19:50,919 log Internal Server Error: /api/get-my-progress-summary/
Traceback (most recent call last):
  File "C:\Github\WildLitz-Capstone\backend\wildlitz\api\views.py", line 273, in get_my_progress_summary
TypeError: unsupported operand type(s) for +: 'int' and 'datetime.timedelta'

During handling of the above exception, another exception occurred:

Traceback (most recent call last):
  File "C:\Github\WildLitz-Capstone\venv\Lib\site-packages\django\core\handlers\exception.py", line 55, in inner
    response = get_response(request)
  File "C:\Github\WildLitz-Capstone\venv\Lib\site-packages\django\core\handlers\base.py", line 197, in _get_response
    response = wrapped_callback(request, *callback_args, **callback_kwargs)
  File "C:\Github\WildLitz-Capstone\venv\Lib\site-packages\django\views\decorators\csrf.py", line 65, in _view_wrapper
    return view_func(request, *args, **kwargs)
  File "C:\Github\WildLitz-Capstone\venv\Lib\site-packages\django\views\generic\base.py", line 105, in view
    return self.dispatch(request, *args, **kwargs)
           ~~~~~~~~~~~~~^^^^^^^^^^^^^^^^^^^^^^^^^^
  File "C:\Github\WildLitz-Capstone\venv\Lib\site-packages\rest_framework\views.py", line 515, in dispatch
    response = self.handle_exception(exc)
  File "C:\Github\WildLitz-Capstone\venv\Lib\site-packages\rest_framework\views.py", line 475, in handle_exception
    self.raise_uncaught_exception(exc)
    ~~~~~~~~~~~~~~~~~~~~~~~~~~~~~^^^^^
  File "C:\Github\WildLitz-Capstone\venv\Lib\site-packages\rest_framework\views.py", line 486, in raise_uncaught_exception
    raise exc
  File "C:\Github\WildLitz-Capstone\venv\Lib\site-packages\rest_framework\views.py", line 512, in dispatch
    response = handler(request, *args, **kwargs)
  File "C:\Github\WildLitz-Capstone\venv\Lib\site-packages\rest_framework\decorators.py", line 50, in handler
    return func(*args, **kwargs)
  File "C:\Github\WildLitz-Capstone\backend\wildlitz\api\views.py", line 289, in get_my_progress_summary
NameError: name 'logger' is not defined
ERROR 2025-10-27 01:19:50,921 basehttp "GET /api/get-my-progress-summary/ HTTP/1.1" 500 108985
ERROR 2025-10-27 01:19:50,921 basehttp "GET /api/get-my-progress-summary/ HTTP/1.1" 500 108985
ERROR 2025-10-27 01:19:51,035 log Internal Server Error: /api/get-my-progress-summary/
Traceback (most recent call last):
  File "C:\Github\WildLitz-Capstone\backend\wildlitz\api\views.py", line 273, in get_my_progress_summary
TypeError: unsupported operand type(s) for +: 'int' and 'datetime.timedelta'

During handling of the above exception, another exception occurred:

Traceback (most recent call last):
  File "C:\Github\WildLitz-Capstone\venv\Lib\site-packages\django\core\handlers\exception.py", line 55, in inner
    response = get_response(request)
  File "C:\Github\WildLitz-Capstone\venv\Lib\site-packages\django\core\handlers\base.py", line 197, in _get_response
    response = wrapped_callback(request, *callback_args, **callback_kwargs)
  File "C:\Github\WildLitz-Capstone\venv\Lib\site-packages\django\views\decorators\csrf.py", line 65, in _view_wrapper
    return view_func(request, *args, **kwargs)
  File "C:\Github\WildLitz-Capstone\venv\Lib\site-packages\django\views\generic\base.py", line 105, in view
    return self.dispatch(request, *args, **kwargs)
           ~~~~~~~~~~~~~^^^^^^^^^^^^^^^^^^^^^^^^^^
  File "C:\Github\WildLitz-Capstone\venv\Lib\site-packages\rest_framework\views.py", line 515, in dispatch
    response = self.handle_exception(exc)
  File "C:\Github\WildLitz-Capstone\venv\Lib\site-packages\rest_framework\views.py", line 475, in handle_exception
    self.raise_uncaught_exception(exc)
    ~~~~~~~~~~~~~~~~~~~~~~~~~~~~~^^^^^
  File "C:\Github\WildLitz-Capstone\venv\Lib\site-packages\rest_framework\views.py", line 486, in raise_uncaught_exception
    raise exc
  File "C:\Github\WildLitz-Capstone\venv\Lib\site-packages\rest_framework\views.py", line 512, in dispatch
    response = handler(request, *args, **kwargs)
  File "C:\Github\WildLitz-Capstone\venv\Lib\site-packages\rest_framework\decorators.py", line 50, in handler
    return func(*args, **kwargs)
  File "C:\Github\WildLitz-Capstone\backend\wildlitz\api\views.py", line 289, in get_my_progress_summary
NameError: name 'logger' is not defined
ERROR 2025-10-27 01:19:51,041 basehttp "GET /api/get-my-progress-summary/ HTTP/1.1" 500 108985
ERROR 2025-10-27 01:19:51,041 basehttp "GET /api/get-my-progress-summary/ HTTP/1.1" 500 108985
ERROR 2025-10-27 01:22:55,703 views Failed to log activity for user 7: The `request` argument must be an instance of `django.http.HttpRequest`, not `rest_framework.request.Request`.
ERROR 2025-10-27 01:23:48,301 views Failed to log activity for user 7: The `request` argument must be an instance of `django.http.HttpRequest`, not `rest_framework.request.Request`.
ERROR 2025-10-27 01:23:59,111 views Failed to log activity for user 7: The `request` argument must be an instance of `django.http.HttpRequest`, not `rest_framework.request.Request`.
ERROR 2025-10-27 01:24:08,905 views Failed to log activity for user 7: The `request` argument must be an instance of `django.http.HttpRequest`, not `rest_framework.request.Request`.
ERROR 2025-10-27 01:24:19,730 views Failed to log activity for user 7: The `request` argument must be an instance of `django.http.HttpRequest`, not `rest_framework.request.Request`.
ERROR 2025-10-27 01:33:49,402 views Failed to log activity for user 7: The `request` argument must be an instance of `django.http.HttpRequest`, not `rest_framework.request.Request`.
ERROR 2025-10-27 01:34:04,444 views Failed to log activity for user 7: The `request` argument must be an instance of `django.http.HttpRequest`, not `rest_framework.request.Request`.
ERROR 2025-10-27 01:34:14,066 views Failed to log activity for user 7: The `request` argument must be an instance of `django.http.HttpRequest`, not `rest_framework.request.Request`.
ERROR 2025-10-27 01:34:23,880 views Failed to log activity for user 7: The `request` argument must be an instance of `django.http.HttpRequest`, not `rest_framework.request.Request`.
ERROR 2025-10-27 01:34:34,072 views Failed to log activity for user 7: The `request` argument must be an instance of `django.http.HttpRequest`, not `rest_framework.request.Request`.
